Workbook

Sheet СОТРУДНИКИ
A1: № | B1: ФАМИЛИЯ ИМЯ ОТЧЕСТВО | C1: ОТПУСК 1 | F1: ОТПУСК 2 | I1: ОТПУСК 3
C2: Начало | D2: Конец | E2: Дней | F2: Начало | G2: Конец | H2: Дней | I2: Начало | J2: Конец | K2: Дней
A3: 1 | B3: ИВАНОВ ИВАН ИВАНОВИЧ | C3: 46032 | D3: 46042 | E3: =IF(AND(C3<>"",D3<>""),D3-C3+1,"") -> 11 | F3: 46218 | G3: 46235 | H3: =IF(AND(F3<>"",G3<>""),G3-F3+1,"") -> 18 | K3: =IF(AND(I3<>"",J3<>""),J3-I3+1,"")
A4: 2 | B4: ПЕТРОВ ПЕТР ПЕТРОВИЧ | C4: 46068 | D4: 46078 | E4: =IF(AND(C4<>"",D4<>""),D4-C4+1,"") -> 11 | F4: 46266 | G4: 46279 | H4: =IF(AND(F4<>"",G4<>""),G4-F4+1,"") -> 14 | K4: =IF(AND(I4<>"",J4<>""),J4-I4+1,"")
A5: 3 | B5: СИДОРОВА МАРИЯ ВЛАДИМИРОВНА | C5: 46082 | D5: 46095 | E5: =IF(AND(C5<>"",D5<>""),D5-C5+1,"") -> 14 | F5: 46305 | G5: 46315 | H5: =IF(AND(F5<>"",G5<>""),G5-F5+1,"") -> 11 | K5: =IF(AND(I5<>"",J5<>""),J5-I5+1,"")
A6: 4 | B6: КОЗЛОВ АЛЕКСЕЙ НИКОЛАЕВИЧ | C6: 46113 | D6: 46122 | E6: =IF(AND(C6<>"",D6<>""),D6-C6+1,"") -> 10 | F6: 46327 | G6: 46336 | H6: =IF(AND(F6<>"",G6<>""),G6-F6+1,"") -> 10 | K6: =IF(AND(I6<>"",J6<>""),J6-I6+1,"")
A7: 5 | B7: МОРОЗОВА ЕЛЕНА СЕРГЕЕВНА | C7: 46152 | D7: 46166 | E7: =IF(AND(C7<>"",D7<>""),D7-C7+1,"") -> 15 | F7: 46371 | G7: 46387 | H7: =IF(AND(F7<>"",G7<>""),G7-F7+1,"") -> 17 | K7: =IF(AND(I7<>"",J7<>""),J7-I7+1,"")
A8: 6 | B8: НИКОЛАЕВ АНДРЕЙ ВИКТОРОВИЧ | C8: 46174 | D8: 46187 | E8: =IF(AND(C8<>"",D8<>""),D8-C8+1,"") -> 14 | H8: =IF(AND(F8<>"",G8<>""),G8-F8+1,"") | K8: =IF(AND(I8<>"",J8<>""),J8-I8+1,"")
A9: 7 | B9: ОРЛОВА ОЛЬГА ИГОРЕВНА | C9: 46204 | D9: 46213 | E9: =IF(AND(C9<>"",D9<>""),D9-C9+1,"") -> 10 | H9: =IF(AND(F9<>"",G9<>""),G9-F9+1,"") | K9: =IF(AND(I9<>"",J9<>""),J9-I9+1,"")
A10: 8 | B10: ВОЛКОВ ДМИТРИЙ АЛЕКСАНДРОВИЧ | C10: 46249 | D10: 46265 | E10: =IF(AND(C10<>"",D10<>""),D10-C10+1,"") -> 17 | H10: =IF(AND(F10<>"",G10<>""),G10-F10+1,"") | K10: =IF(AND(I10<>"",J10<>""),J10-I10+1,"")
A11: ИТОГО дней отпуска: | E11: =SUM(E3:E10,H3:H10,K3:K10) -> 172

Sheet ГРАФИК ОТПУСКОВ
A1: № | B1: ФИО СОТРУДНИКА | C1: ЯНВ | AH1: ФЕВ | BJ1: МАР | CO1: АПР | DS1: МАЙ | EX1: ИЮН | GB1: ИЮЛ | HG1: АВГ | IL1: СЕН | JP1: ОКТ | KU1: НОЯ | LY1: ДЕК
C2: 46023 | D2: 46024 | E2: 46025 | F2: 46026 | G2: 46027 | H2: 46028 | I2: 46029 | J2: 46030 | K2: 46031 | L2: 46032 | M2: 46033 | N2: 46034 | O2: 46035 | P2: 46036 | Q2: 46037 | R2: 46038 | S2: 46039 | T2: 46040 | U2: 46041 | V2: 46042 | W2: 46043 | X2: 46044 | Y2: 46045 | Z2: 46046 | AA2: 46047 | AB2: 46048 | AC2: 46049 | AD2: 46050 | AE2: 46051 | AF2: 46052 | AG2: 46053 | AH2: 46054 | AI2: 46055 | AJ2: 46056 | AK2: 46057 | AL2: 46058 | AM2: 46059 | AN2: 46060 | AO2: 46061 | AP2: 46062 | AQ2: 46063 | AR2: 46064 | AS2: 46065 | AT2: 46066 | AU2: 46067 | AV2: 46068 | AW2: 46069 | AX2: 46070 | AY2: 46071 | AZ2: 46072 | BA2: 46073 | BB2: 46074 | BC2: 46075 | BD2: 46076 | BE2: 46077 | BF2: 46078 | BG2: 46079 | BH2: 46080 | BI2: 46081 | BJ2: 46082 | BK2: 46083 | BL2: 46084 | BM2: 46085 | BN2: 46086 | BO2: 46087 | BP2: 46088 | BQ2: 46089 | BR2: 46090 | BS2: 46091 | BT2: 46092 | BU2: 46093 | BV2: 46094 | BW2: 46095 | BX2: 46096 | BY2: 46097 | BZ2: 46098 | CA2: 46099 | CB2: 46100 | CC2: 46101 | CD2: 46102 | CE2: 46103 | CF2: 46104 | CG2: 46105 | CH2: 46106 | CI2: 46107 | CJ2: 46108 | CK2: 46109 | CL2: 46110 | CM2: 46111 | CN2: 46112 | CO2: 46113 | CP2: 46114 | CQ2: 46115 | CR2: 46116 | CS2: 46117 | CT2: 46118 | CU2: 46119 | CV2: 46120 | CW2: 46121 | CX2: 46122 | CY2: 46123 | CZ2: 46124 | DA2: 46125 | DB2: 46126 | DC2: 46127 | DD2: 46128 | DE2: 46129 | DF2: 46130 | DG2: 46131 | DH2: 46132 | DI2: 46133 | DJ2: 46134 | DK2: 46135 | DL2: 46136 | DM2: 46137 | DN2: 46138 | DO2: 46139 | DP2: 46140 | DQ2: 46141 | DR2: 46142 | DS2: 46143 | DT2: 46144 | DU2: 46145 | DV2: 46146 | DW2: 46147 | DX2: 46148 | DY2: 46149 | DZ2: 46150 | EA2: 46151 | EB2: 46152 | EC2: 46153 | ED2: 46154 | EE2: 46155 | EF2: 46156 | EG2: 46157 | EH2: 46158 | EI2: 46159 | EJ2: 46160 | EK2: 46161 | EL2: 46162 | EM2: 46163 | EN2: 46164 | EO2: 46165 | EP2: 46166 | EQ2: 46167 | ER2: 46168 | ES2: 46169 | ET2: 46170 | EU2: 46171 | EV2: 46172 | EW2: 46173 | EX2: 46174 | EY2: 46175 | EZ2: 46176 | FA2: 46177 | FB2: 46178 | FC2: 46179 | FD2: 46180 | FE2: 46181 | FF2: 46182 | FG2: 46183 | FH2: 46184 | FI2: 46185 | FJ2: 46186 | FK2: 46187 | FL2: 46188 | FM2: 46189 | FN2: 46190 | FO2: 46191 | FP2: 46192 | FQ2: 46193 | FR2: 46194 | FS2: 46195 | FT2: 46196 | FU2: 46197 | FV2: 46198 | FW2: 46199 | FX2: 46200 | FY2: 46201 | FZ2: 46202 | GA2: 46203 | GB2: 46204 | GC2: 46205 | GD2: 46206 | GE2: 46207 | GF2: 46208 | GG2: 46209 | GH2: 46210 | GI2: 46211 | GJ2: 46212 | GK2: 46213 | GL2: 46214 | GM2: 46215 | GN2: 46216 | GO2: 46217 | GP2: 46218 | GQ2: 46219 | GR2: 46220 | GS2: 46221 | GT2: 46222 | GU2: 46223 | GV2: 46224 | GW2: 46225 | GX2: 46226 | GY2: 46227 | GZ2: 46228 | HA2: 46229 | HB2: 46230 | HC2: 46231 | HD2: 46232 | HE2: 46233 | HF2: 46234 | HG2: 46235 | HH2: 46236 | HI2: 46237 | HJ2: 46238 | HK2: 46239 | HL2: 46240 | HM2: 46241 | HN2: 46242 | HO2: 46243 | HP2: 46244 | HQ2: 46245 | HR2: 46246 | HS2: 46247 | HT2: 46248 | HU2: 46249 | HV2: 46250 | HW2: 46251 | HX2: 46252 | HY2: 46253 | HZ2: 46254 | IA2: 46255 | IB2: 46256 | IC2: 46257 | ID2: 46258 | IE2: 46259 | IF2: 46260 | IG2: 46261 | IH2: 46262 | II2: 46263 | IJ2: 46264 | IK2: 46265 | IL2: 46266 | IM2: 46267 | IN2: 46268 | IO2: 46269 | IP2: 46270 | IQ2: 46271 | IR2: 46272 | IS2: 46273 | IT2: 46274 | IU2: 46275 | IV2: 46276 | IW2: 46277 | IX2: 46278 | IY2: 46279 | IZ2: 46280 | JA2: 46281 | JB2: 46282 | JC2: 46283 | JD2: 46284 | JE2: 46285 | JF2: 46286 | JG2: 46287 | JH2: 46288 | JI2: 46289 | JJ2: 46290 | JK2: 46291 | JL2: 46292 | JM2: 46293 | JN2: 46294 | JO2: 46295 | JP2: 46296 | JQ2: 46297 | JR2: 46298 | JS2: 46299 | JT2: 46300 | JU2: 46301 | JV2: 46302 | JW2: 46303 | JX2: 46304 | JY2: 46305 | JZ2: 46306 | KA2: 46307 | KB2: 46308 | KC2: 46309 | KD2: 46310 | KE2: 46311 | KF2: 46312 | KG2: 46313 | KH2: 46314 | KI2: 46315 | KJ2: 46316 | KK2: 46317 | KL2: 46318 | KM2: 46319 | KN2: 46320 | KO2: 46321 | KP2: 46322 | KQ2: 46323 | KR2: 46324 | KS2: 46325 | KT2: 46326 | KU2: 46327 | KV2: 46328 | KW2: 46329 | KX2: 46330 | KY2: 46331 | KZ2: 46332 | LA2: 46333 | LB2: 46334 | LC2: 46335 | LD2: 46336 | LE2: 46337 | LF2: 46338 | LG2: 46339 | LH2: 46340 | LI2: 46341 | LJ2: 46342 | LK2: 46343 | LL2: 46344 | LM2: 46345 | LN2: 46346 | LO2: 46347 | LP2: 46348 | LQ2: 46349 | LR2: 46350 | LS2: 46351 | LT2: 46352 | LU2: 46353 | LV2: 46354 | LW2: 46355 | LX2: 46356 | LY2: 46357 | LZ2: 46358 | MA2: 46359 | MB2: 46360 | MC2: 46361 | MD2: 46362 | ME2: 46363 | MF2: 46364 | MG2: 46365 | MH2: 46366 | MI2: 46367 | MJ2: 46368 | MK2: 46369 | ML2: 46370 | MM2: 46371 | MN2: 46372 | MO2: 46373 | MP2: 46374 | MQ2: 46375 | MR2: 46376 | MS2: 46377 | MT2: 46378 | MU2: 46379 | MV2: 46380 | MW2: 46381 | MX2: 46382 | MY2: 46383 | MZ2: 46384 | NA2: 46385 | NB2: 46386 | NC2: 46387
C3: Чт ✶ | D3: Пт ✶ | E3: Сб ✶ | F3: Вс ✶ | G3: Пн ✶ | H3: Вт ✶ | I3: Ср ✶ | J3: Чт ✶ | K3: Пт ✶ | L3: Сб | M3: Вс | N3: Пн | O3: Вт | P3: Ср | Q3: Чт | R3: Пт | S3: Сб | T3: Вс | U3: Пн | V3: Вт | W3: Ср | X3: Чт | Y3: Пт | Z3: Сб | AA3: Вс | AB3: Пн | AC3: Вт | AD3: Ср | AE3: Чт | AF3: Пт | AG3: Сб | AH3: Вс | AI3: Пн | AJ3: Вт | AK3: Ср | AL3: Чт | AM3: Пт | AN3: Сб | AO3: Вс | AP3: Пн | AQ3: Вт | AR3: Ср | AS3: Чт | AT3: Пт | AU3: Сб | AV3: Вс | AW3: Пн | AX3: Вт | AY3: Ср | AZ3: Чт | BA3: Пт ◐ | BB3: Сб ⚒ | BC3: Вс | BD3: Пн ✶ | BE3: Вт | BF3: Ср | BG3: Чт | BH3: Пт | BI3: Сб | BJ3: Вс | BK3: Пн | BL3: Вт | BM3: Ср | BN3: Чт | BO3: Пт | BP3: Сб ◐ | BQ3: Вс ✶ | BR3: Пн | BS3: Вт | BT3: Ср | BU3: Чт | BV3: Пт | BW3: Сб | BX3: Вс | BY3: Пн | BZ3: Вт | CA3: Ср | CB3: Чт | CC3: Пт | CD3: Сб | CE3: Вс | CF3: Пн | CG3: Вт | CH3: Ср | CI3: Чт | CJ3: Пт | CK3: Сб | CL3: Вс | CM3: Пн | CN3: Вт | CO3: Ср | CP3: Чт | CQ3: Пт | CR3: Сб | CS3: Вс | CT3: Пн | CU3: Вт | CV3: Ср | CW3: Чт | CX3: Пт | CY3: Сб | CZ3: Вс | DA3: Пн | DB3: Вт | DC3: Ср | DD3: Чт | DE3: Пт | DF3: Сб | DG3: Вс | DH3: Пн | DI3: Вт | DJ3: Ср | DK3: Чт | DL3: Пт | DM3: Сб | DN3: Вс | DO3: Пн | DP3: Вт | DQ3: Ср | DR3: Чт | DS3: Пт ✶ | DT3: Сб | DU3: Вс | DV3: Пн | DW3: Вт | DX3: Ср | DY3: Чт | DZ3: Пт ◐ | EA3: Сб ✶ | EB3: Вс | EC3: Пн | ED3: Вт | EE3: Ср | EF3: Чт | EG3: Пт | EH3: Сб | EI3: Вс | EJ3: Пн | EK3: Вт | EL3: Ср | EM3: Чт | EN3: Пт | EO3: Сб | EP3: Вс | EQ3: Пн | ER3: Вт | ES3: Ср | ET3: Чт | EU3: Пт | EV3: Сб | EW3: Вс | EX3: Пн | EY3: Вт | EZ3: Ср | FA3: Чт | FB3: Пт | FC3: Сб | FD3: Вс | FE3: Пн | FF3: Вт | FG3: Ср | FH3: Чт ◐ | FI3: Пт ✶ | FJ3: Сб | FK3: Вс | FL3: Пн | FM3: Вт | FN3: Ср | FO3: Чт | FP3: Пт | FQ3: Сб | FR3: Вс | FS3: Пн | FT3: Вт | FU3: Ср | FV3: Чт | FW3: Пт | FX3: Сб | FY3: Вс | FZ3: Пн | GA3: Вт | GB3: Ср | GC3: Чт | GD3: Пт | GE3: Сб | GF3: Вс | GG3: Пн | GH3: Вт | GI3: Ср | GJ3: Чт | GK3: Пт | GL3: Сб | GM3: Вс | GN3: Пн | GO3: Вт | GP3: Ср | GQ3: Чт | GR3: Пт | GS3: Сб | GT3: Вс | GU3: Пн | GV3: Вт | GW3: Ср | GX3: Чт | GY3: Пт | GZ3: Сб | HA3: Вс | HB3: Пн | HC3: Вт | HD3: Ср | HE3: Чт | HF3: Пт | HG3: Сб | HH3: Вс | HI3: Пн | HJ3: Вт | HK3: Ср | HL3: Чт | HM3: Пт | HN3: Сб | HO3: Вс | HP3: Пн | HQ3: Вт | HR3: Ср | HS3: Чт | HT3: Пт | HU3: Сб | HV3: Вс | HW3: Пн | HX3: Вт | HY3: Ср | HZ3: Чт | IA3: Пт | IB3: Сб | IC3: Вс | ID3: Пн | IE3: Вт | IF3: Ср | IG3: Чт | IH3: Пт | II3: Сб | IJ3: Вс | IK3: Пн | IL3: Вт | IM3: Ср | IN3: Чт | IO3: Пт | IP3: Сб | IQ3: Вс | IR3: Пн | IS3: Вт | IT3: Ср | IU3: Чт | IV3: Пт | IW3: Сб | IX3: Вс | IY3: Пн | IZ3: Вт | JA3: Ср | JB3: Чт | JC3: Пт | JD3: Сб | JE3: Вс | JF3: Пн | JG3: Вт | JH3: Ср | JI3: Чт | JJ3: Пт | JK3: Сб | JL3: Вс | JM3: Пн | JN3: Вт | JO3: Ср | JP3: Чт | JQ3: Пт | JR3: Сб | JS3: Вс | JT3: Пн | JU3: Вт | JV3: Ср | JW3: Чт | JX3: Пт | JY3: Сб | JZ3: Вс | KA3: Пн | KB3: Вт | KC3: Ср | KD3: Чт | KE3: Пт | KF3: Сб | KG3: Вс | KH3: Пн | KI3: Вт | KJ3: Ср | KK3: Чт | KL3: Пт | KM3: Сб | KN3: Вс | KO3: Пн | KP3: Вт | KQ3: Ср | KR3: Чт | KS3: Пт | KT3: Сб | KU3: Вс | KV3: Пн | KW3: Вт ◐ | KX3: Ср ✶ | KY3: Чт | KZ3: Пт | LA3: Сб | LB3: Вс | LC3: Пн | LD3: Вт | LE3: Ср | LF3: Чт | LG3: Пт | LH3: Сб ⚒ | LI3: Вс | LJ3: Пн | LK3: Вт | LL3: Ср | LM3: Чт | LN3: Пт | LO3: Сб | LP3: Вс | LQ3: Пн | LR3: Вт | LS3: Ср | LT3: Чт | LU3: Пт | LV3: Сб | LW3: Вс | LX3: Пн | LY3: Вт | LZ3: Ср | MA3: Чт | MB3: Пт | MC3: Сб | MD3: Вс | ME3: Пн | MF3: Вт | MG3: Ср | MH3: Чт | MI3: Пт | MJ3: Сб | MK3: Вс | ML3: Пн | MM3: Вт | MN3: Ср | MO3: Чт | MP3: Пт | MQ3: Сб | MR3: Вс | MS3: Пн | MT3: Вт | MU3: Ср | MV3: Чт | MW3: Пт | MX3: Сб | MY3: Вс | MZ3: Пн | NA3: Вт | NB3: Ср | NC3: Чт ◐
